2018-02-12 13:41:15,087 ; DEBUG ; chempiler_client ; MainThread ; User Input:
XML file: C:\Users\group\Documents\Chempiler\graph\chemputer_rig_3_sildenafil.graphml
Command file: C:\Users\group\Documents\Chempiler\tests\sildenafil.chasm
Simulation: n
2018-02-12 13:41:15,244 ; DEBUG ; Chemputer_Device_API ; valve_reagents_1 TCP thread ; Clear errors DONE.
2018-02-12 13:41:15,244 ; DEBUG ; Chemputer_Device_API ; valve_reagents_1 TCP thread ; Actuation SUCCESS!
2018-02-12 13:41:15,259 ; DEBUG ; Chemputer_Device_API ; valve_reagents_2 TCP thread ; Clear errors DONE.
2018-02-12 13:41:15,259 ; DEBUG ; Chemputer_Device_API ; valve_reagents_2 TCP thread ; Actuation SUCCESS!
2018-02-12 13:41:15,259 ; DEBUG ; Chemputer_Device_API ; valve_solvents TCP thread ; Clear errors DONE.
2018-02-12 13:41:15,275 ; DEBUG ; Chemputer_Device_API ; valve_solvents TCP thread ; Actuation SUCCESS!
2018-02-12 13:41:15,275 ; DEBUG ; Chemputer_Device_API ; valve_reactor TCP thread ; Clear errors DONE.
2018-02-12 13:41:15,275 ; DEBUG ; Chemputer_Device_API ; valve_reactor TCP thread ; Actuation SUCCESS!
2018-02-12 13:41:16,150 ; DEBUG ; Chemputer_Device_API ; valve_solvents TCP thread ; FAILURE: no magnet found.
2018-02-12 13:41:16,291 ; DEBUG ; Chemputer_Device_API ; valve_reagents_1 TCP thread ; Move DONE
2018-02-12 13:41:16,337 ; DEBUG ; Chemputer_Device_API ; valve_reagents_2 TCP thread ; Move DONE
2018-02-12 13:41:16,400 ; DEBUG ; Chemputer_Device_API ; valve_reactor TCP thread ; Move DONE
2018-02-12 13:43:04,731 ; DEBUG ; chempiler_client ; MainThread ; User Input:
XML file: C:\Users\group\Documents\Chempiler\graph\chemputer_rig_3_sildenafil.graphml
Command file: C:\Users\group\Documents\Chempiler\tests\sildenafil.chasm
Simulation: n
2018-02-12 13:43:25,857 ; ERROR ; Chemputer_Device_API ; MainThread ; Unable to connect to host device: IP 192.168.1.29 did not respond.
Traceback (most recent call last):
  File "C:\Users\group\Documents\Chempiler\platform_server\modules\pv_api\Chemputer_Device_API.py", line 143, in connect_to_server
    self.tcp.connect((self.address, TCP_PORT))
TimeoutError: [WinError 10060] A connection attempt failed because the connected party did not properly respond after a period of time, or established connection failed because connected host has failed to respond
2018-02-12 13:46:33,181 ; DEBUG ; chempiler_client ; MainThread ; User Input:
XML file: C:\Users\group\Documents\Chempiler\graph\chemputer_rig_3_sildenafil.graphml
Command file: C:\Users\group\Documents\Chempiler\tests\sildenafil.chasm
Simulation: n
2018-02-12 13:46:54,323 ; ERROR ; Chemputer_Device_API ; MainThread ; Unable to connect to host device: IP 192.168.1.29 did not respond.
Traceback (most recent call last):
  File "C:\Users\group\Documents\Chempiler\platform_server\modules\pv_api\Chemputer_Device_API.py", line 143, in connect_to_server
    self.tcp.connect((self.address, TCP_PORT))
TimeoutError: [WinError 10060] A connection attempt failed because the connected party did not properly respond after a period of time, or established connection failed because connected host has failed to respond
